Traceback (most recent call last):
  File "c:\users\sahil choudhary\appdata\local\programs\python\python37-32\lib\site-packages\jupyter_cache\executors\utils.py", line 56, in single_nb_execution
    record_timing=False,
  File "c:\users\sahil choudhary\appdata\local\programs\python\python37-32\lib\site-packages\nbclient\client.py", line 1112, in execute
    return NotebookClient(nb=nb, resources=resources, km=km, **kwargs).execute()
  File "c:\users\sahil choudhary\appdata\local\programs\python\python37-32\lib\site-packages\nbclient\util.py", line 74, in wrapped
    return just_run(coro(*args, **kwargs))
  File "c:\users\sahil choudhary\appdata\local\programs\python\python37-32\lib\site-packages\nbclient\util.py", line 53, in just_run
    return loop.run_until_complete(coro)
  File "c:\users\sahil choudhary\appdata\local\programs\python\python37-32\lib\asyncio\base_events.py", line 587, in run_until_complete
    return future.result()
  File "c:\users\sahil choudhary\appdata\local\programs\python\python37-32\lib\site-packages\nbclient\client.py", line 554, in async_execute
    cell, index, execution_count=self.code_cells_executed + 1
  File "c:\users\sahil choudhary\appdata\local\programs\python\python37-32\lib\site-packages\nbclient\client.py", line 857, in async_execute_cell
    self._check_raise_for_error(cell, exec_reply)
  File "c:\users\sahil choudhary\appdata\local\programs\python\python37-32\lib\site-packages\nbclient\client.py", line 760, in _check_raise_for_error
    raise CellExecutionError.from_cell_and_msg(cell, exec_reply_content)
nbclient.exceptions.CellExecutionError: An error occurred while executing the following cell:
------------------
folder=cwd/"_build/subfolder"
for file in folder.iterdir():
    print(file)
------------------

[1;31m---------------------------------------------------------------------------[0m
[1;31mFileNotFoundError[0m                         Traceback (most recent call last)
[1;32m<ipython-input-16-c8522528660c>[0m in [0;36m<module>[1;34m[0m
[0;32m      1[0m [0mfolder[0m[1;33m=[0m[0mcwd[0m[1;33m/[0m[1;34m"_build/subfolder"[0m[1;33m[0m[1;33m[0m[0m
[1;32m----> 2[1;33m [1;32mfor[0m [0mfile[0m [1;32min[0m [0mfolder[0m[1;33m.[0m[0miterdir[0m[1;33m([0m[1;33m)[0m[1;33m:[0m[1;33m[0m[1;33m[0m[0m
[0m[0;32m      3[0m     [0mprint[0m[1;33m([0m[0mfile[0m[1;33m)[0m[1;33m[0m[1;33m[0m[0m

[1;32mc:\users\sahil choudhary\appdata\local\programs\python\python37-32\lib\pathlib.py[0m in [0;36miterdir[1;34m(self)[0m
[0;32m   1100[0m         [1;32mif[0m [0mself[0m[1;33m.[0m[0m_closed[0m[1;33m:[0m[1;33m[0m[1;33m[0m[0m
[0;32m   1101[0m             [0mself[0m[1;33m.[0m[0m_raise_closed[0m[1;33m([0m[1;33m)[0m[1;33m[0m[1;33m[0m[0m
[1;32m-> 1102[1;33m         [1;32mfor[0m [0mname[0m [1;32min[0m [0mself[0m[1;33m.[0m[0m_accessor[0m[1;33m.[0m[0mlistdir[0m[1;33m([0m[0mself[0m[1;33m)[0m[1;33m:[0m[1;33m[0m[1;33m[0m[0m
[0m[0;32m   1103[0m             [1;32mif[0m [0mname[0m [1;32min[0m [1;33m{[0m[1;34m'.'[0m[1;33m,[0m [1;34m'..'[0m[1;33m}[0m[1;33m:[0m[1;33m[0m[1;33m[0m[0m
[0;32m   1104[0m                 [1;31m# Yielding a path object for these makes little sense[0m[1;33m[0m[1;33m[0m[1;33m[0m[0m

[1;31mFileNotFoundError[0m: [WinError 3] The system cannot find the path specified: 'C:\\Users\\Sahil Choudhary\\Book\\Python\\Chapter files\\_build\\subfolder'
FileNotFoundError: [WinError 3] The system cannot find the path specified: 'C:\\Users\\Sahil Choudhary\\Book\\Python\\Chapter files\\_build\\subfolder'

